Workbook

Sheet Inputs
A1: Inputs: every figure taken from the TriFlow data pack
A2: Blue = taken from an exhibit (source in column C). Yellow = my assumption, stated as such. Every other sheet references these cells.
A4: Item | B4: Value | C4: Source
A5: Revenue, last twelve months | B5: 8400000 | C5: Exhibit 1
A6: Restoration revenue | B6: 3780000 | C6: Exhibit 1
A7: Restoration gross margin | B7: 0.27 | C7: Exhibit 1
A8: Maintenance Program revenue | B8: 2520000 | C8: Exhibit 1
A9: Maintenance gross margin | B9: 0.64 | C9: Exhibit 1
A10: Equipment service and parts revenue | B10: 1764000 | C10: Exhibit 1
A11: Equipment gross margin | B11: 0.19 | C11: Exhibit 1
A12: Licensing revenue | B12: 336000 | C12: Exhibit 1
A13: Licensing gross margin | B13: 0.95 | C13: Exhibit 1
A14: Adjusted EBITDA | B14: 1500000 | C14: Exhibit 1 note
A15: Revenue growth over the last two years | B15: 0.14 | C15: Exhibit 1 note
A16: Recurring share of revenue, two years ago | B16: 0.32 | C16: Exhibit 1 note
... A67: Trade-show spend, LTM | B67: 41000 | C67: Exhibit 6 / 9

Sheet Unit economics
A1: Unit economics by line: where the gross profit actually is
A2: All formulas. Gross profit = revenue x gross margin from Exhibit 1.
A4: Line | B4: Revenue | C4: Share of revenue | D4: Gross profit | E4: Share of gross profit | F4: Units | G4: GP per unit
A5: Restoration | B5: =Inputs!$B$6 -> 3780000 | C5: =B5/B$9 -> 0.45 | D5: =B5*Inputs!$B$7 -> 1020600 | E5: =D5/D$9 -> 0.31042412 | F5: =Inputs!$B$21 -> 58 | G5: =D5/F5 -> 17596.552
A6: Maintenance Program | B6: =Inputs!$B$8 -> 2520000 | C6: =B6/B$9 -> 0.3 | D6: =B6*Inputs!$B$9 -> 1612800 | E6: =D6/D$9 -> 0.49054676 | F6: =Inputs!$B$30 -> 424 | G6: =D6/F6 -> 3803.7736
A7: Equipment service and parts | B7: =Inputs!$B$10 -> 1764000 | C7: =B7/B$9 -> 0.21 | D7: =B7*Inputs!$B$11 -> 335160 | E7: =D7/D$9 -> 0.10194175
A8: Licensing | B8: =Inputs!$B$12 -> 336000 | C8: =B8/B$9 -> 0.04 | D8: =B8*Inputs!$B$13 -> 319200 | E8: =D8/D$9 -> 0.097087379
A9: Total | B9: =SUM(B5:B8) -> 8400000 | C9: =SUM(C5:C8) -> 1 | D9: =SUM(D5:D8) -> 3287760 | E9: =SUM(E5:E8) -> 1
A10: Blended gross margin (check against Exhibit 1: 39.1%) | B10: =D9/B9 -> 0.3914
A12: Per-unit figures
A13: Average Restoration job, revenue | B13: =Inputs!$B$6/Inputs!$B$21 -> 65172.414
A14: Average Restoration job, gross profit (blended 27%) | B14: =B13*Inputs!$B$7 -> 17596.552
A15: Maintenance revenue per asset per year | B15: =Inputs!$B$8/Inputs!$B$30 -> 5943.3962
A16: Maintenance gross profit per asset per year | B16: =B15*Inputs!$B$9 -> 3803.7736
A17: Maintenance revenue per asset over a five-year term (no escalator) | B17: =B15*5 -> 29716.981
A18: Maintenance gross profit per asset over a five-year term (no escalator) | B18: =B16*5 -> 19018.868
A19: Maintenance: share of revenue | B19: =C6 -> 0.3
A20: Maintenance: share of gross profit | B20: =E6 -> 0.49054676
A21: Restoration: share of revenue | B21: =C5 -> 0.45
A22: Restoration: share of gross profit | B22: =E5 -> 0.31042412
A23: Recurring share of revenue today (check: pack says 30%) | B23: =Inputs!$B$8/Inputs!$B$5 -> 0.3

Sheet Capacity
A1: Capacity: the crews are full, and growth has been bought from subcontractors
A2: Assumption A1 (yellow): all subcontracted revenue is Restoration work. This is the reading that makes Exhibit 5 reconcile; confirmed or corrected by Amanda's answer to my question 2.
A4: Measure | B4: Value | C4: How it is derived
A5: Crew-weeks available per year | B5: =Inputs!$B$17*Inputs!$B$18 -> 220 | C5: 5 crews x 44 weeks (Exhibit 5)
A6: Crew-weeks needed for all 58 Restoration jobs | B6: =Inputs!$B$21*Inputs!$B$19 -> 150.8 | C6: 58 x 2.6
A7: Crew-weeks needed for all 424 Maintenance visits | B7: =Inputs!$B$22*Inputs!$B$20 -> 148.4 | C7: 424 x 0.35
A8: Total crew-weeks of work delivered | B8: =B6+B7 -> 299.2 | C8: Sum
A9: Work in excess of own capacity (crew-weeks) | B9: =B8-B5 -> 79.2 | C9: Work minus capacity. The gap has to be subcontracted work.
A10: Overrun as a share of capacity | B10: =B9/B5 -> 0.36
A11: Restoration jobs implied subcontracted (A1) | B11: =B9/Inputs!$B$19 -> 30.461538 | C11: Overrun crew-weeks / 2.6 per job
A12: Average revenue per subcontracted job (A1) | B12: =Inputs!$B$25/B11 -> 53871.212 | C12: $1.641M / implied jobs. Lands inside the municipal ticket range ($22K-65K), which supports A1.
A13: Restoration jobs self-performed (A1) | B13: =Inputs!$B$21-B11 -> 27.538462 | C13: 58 minus subcontracted
A14: Crew-weeks used by self-performed Restoration | B14: =B13*Inputs!$B$19 -> 71.6
A15: Crew-weeks used by own crews in total | B15: =B14+B7 -> 220 | C15: Self-performed Restoration plus every Maintenance visit
A16: Utilization of own crews | B16: =B15/B5 -> 1 | C16: This lands at 100%. The crews are full to the week.
A17: Self-performed Restoration revenue (A1) | B17: =Inputs!$B$6-Inputs!$B$25 -> 2139000 | C17: Restoration revenue minus subcontracted revenue
A18: Gross profit on subcontracted work | B18: =Inputs!$B$25*Inputs!$B$26 -> 246150 | C18: $1.641M x 15%
A19: Gross profit on self-performed Restoration (A1) | B19: =Inputs!$B$6*Inputs!$B$7-B18 -> 774450 | C19: Total Restoration GP minus subcontracted GP
A20: Gross margin on self-performed Restoration (A1) | B20: =B19/B17 -> 0.36206171 | C20: Implied. Reasonable next to the 45% blended self-performed figure.
A21: Gross profit per self-performed Restoration job | B21: =B19/B13 -> 28122.486
A22: Gross profit per subcontracted Restoration job | B22: =B18/B11 -> 8080.6818
A23: Gross profit given up per job handed to a subcontractor | B23: =B21-B22 -> 20041.804 | C23: The price of growing without crews
A24: Gross profit given up in total, LTM (A1) | B24: =B23*B11 -> 610504.19 | C24: About 40% of adjusted EBITDA
A25: Gross profit per crew-week, self-performed Restoration | B25: =B21/Inputs!$B$19 -> 10816.341 | C25: GP per job / 2.6
A26: Gross profit per crew-week, Maintenance visit | B26: ='Unit economics'!$B$16/Inputs!$B$20 -> 10867.925 | C26: GP per asset-year / 0.35
A27: Revenue growth in dollars over two years | B27: =Inputs!$B$5-Inputs!$B$5/(1+Inputs!$B$15) -> 1031578.9 | C27: Exhibit 1 note
A28: Growth in subcontractor cost over the same two years | B28: =Inputs!$B$27-Inputs!$B$28 -> 818000 | C28: Exhibit 5
A29: Subcontractor cost growth as a share of revenue growth | B29: =B28/B27 -> 0.79295918 | C29: Most of the growth was bought
A30: Value of a sixth crew: crew-weeks | B30: =Inputs!$B$18 -> 44 | C30: 44 weeks
A31: if used to bring subcontracted Restoration in-house: jobs | B31: =B30/Inputs!$B$19 -> 16.923077
A32: gross profit recovered per year | B32: =B31*B23 -> 339168.99 | C32: Jobs x GP given up per job
A33: if used for Maintenance visits: assets served | B33: =B30/Inputs!$B$20 -> 125.71429
A34: gross profit per year at Maintenance economics | B34: =B33*'Unit economics'!$B$16 -> 478188.68 | C34: Before the cost of the crew. Job-level margin already carries crew labor on delivered work, so the real cost to net out is equipment, idle weeks, and the licensing path in the constrained state. Needs 126 enrolled assets, which this plan does not yet produce.

Sheet Lead sources
A1: Lead sources: Exhibit 6 with the arithmetic the company has not done
A2: Gross profit uses the blended Restoration margin of 27%. Exhibit 6 counts new customers only, and mixes cohorts: this year's inquiries next to wins whose first contact was mostly more than a year ago (Exhibit 7).
A4: Source | B4: Inquiries | C4: Qualified | D4: Site visits | E4: Won | F4: Revenue won | G4: Media cost | H4: Inquiry to win | I4: Revenue per win | J4: Gross profit (27%) | K4: GP after media cost | L4: Share of new revenue
A5: Paid search | B5: 210 | C5: 31 | D5: 8 | E5: 2 | F5: 46000 | G5: =Inputs!$B$66 -> 34000 | H5: =E5/B5 -> 0.0095238095 | I5: =F5/E5 -> 23000 | J5: =F5*Inputs!$B$7 -> 12420 | K5: =J5-G5 -> -21580 | L5: =F5/F$11 -> 0.022395326
A6: Trade-show booth | B6: 96 | C6: 22 | D6: 6 | E6: 2 | F6: 88000 | G6: =Inputs!$B$67 -> 41000 | H6: =E6/B6 -> 0.020833333 | I6: =F6/E6 -> 44000 | J6: =F6*Inputs!$B$7 -> 23760 | K6: =J6-G6 -> -17240 | L6: =F6/F$11 -> 0.042843233
A7: Inbound web form (organic) | B7: 64 | C7: 19 | D7: 9 | E7: 4 | F7: 173000 | G7: 0 | H7: =E7/B7 -> 0.0625 | I7: =F7/E7 -> 43250 | J7: =F7*Inputs!$B$7 -> 46710 | K7: =J7-G7 -> 46710 | L7: =F7/F$11 -> 0.084225901
A8: Referral from an existing customer | B8: 22 | C8: 20 | D8: 17 | E8: 11 | F8: 721000 | G8: 0 | H8: =E8/B8 -> 0.5 | I8: =F8/E8 -> 65545.455 | J8: =F8*Inputs!$B$7 -> 194670 | K8: =J8-G8 -> 194670 | L8: =F8/F$11 -> 0.3510224
A9: Introduction from a consulting engineer | B9: 14 | C9: 13 | D9: 11 | E9: 7 | F9: 902000 | G9: 0 | H9: =E9/B9 -> 0.5 | I9: =F9/E9 -> 128857.14 | J9: =F9*Inputs!$B$7 -> 243540 | K9: =J9-G9 -> 243540 | L9: =F9/F$11 -> 0.43914314
A10: Outbound calling (one salesperson) | B10: 41 | C10: 12 | D10: 5 | E10: 2 | F10: 124000 | G10: 0 | H10: =E10/B10 -> 0.048780488 | I10: =F10/E10 -> 62000 | J10: =F10*Inputs!$B$7 -> 33480 | K10: =J10-G10 -> 33480 | L10: =F10/F$11 -> 0.06037001
A11: Total | B11: =SUM(B5:B10) -> 447 | C11: =SUM(C5:C10) -> 117 | D11: =SUM(D5:D10) -> 56 | E11: =SUM(E5:E10) -> 28 | F11: =SUM(F5:F10) -> 2054000 | G11: =SUM(G5:G10) -> 75000 | H11: =E11/B11 -> 0.062639821 | I11: =F11/E11 -> 73357.143 | J11: =SUM(J5:J10) -> 554580 | K11: =SUM(K5:K10) -> 479580 | L11: =SUM(L5:L10) -> 1
A13: Referral plus engineer introductions: wins | B13: =E8+E9 -> 18
A14: Referral plus engineer introductions: revenue | B14: =F8+F9 -> 1623000
A15: share of new-customer revenue | B15: =B14/F11 -> 0.79016553
A16: share of new-customer wins | B16: =B13/E11 -> 0.64285714
A17: Paid search plus trade show: revenue | B17: =F5+F6 -> 134000
A18: gross profit after media cost | B18: =K5+K6 -> -38820
A19: Repeat-customer Restoration revenue (Ex 1 minus Ex 6) | B19: =Inputs!$B$6-F11 -> 1726000
A20: Repeat-customer Restoration jobs (Ex 5 minus Ex 6) | B20: =Inputs!$B$21-E11 -> 30
A21: Revenue from existing customers, all lines | B21: =Inputs!$B$5-F11 -> 6346000
A22: share of total revenue | B22: =B21/Inputs!$B$5 -> 0.75547619
A23: Site visit to win, referral and engineer | B23: =(E8+E9)/(D8+D9) -> 0.64285714
A24: Site visit to win, paid and trade show | B24: =(E5+E6)/(D5+D6) -> 0.28571429

Sheet Installed base
A1: Installed base: the recurring line, what it is worth and what is leaking
A2: All figures per asset use the Exhibit 1 / Exhibit 3 averages. No assumptions on this sheet.
A4: Measure | B4: Value | C4: Derivation
A5: Share of restored assets that receive maintenance | B5: =Inputs!$B$30/Inputs!$B$29 -> 0.37192982 | C5: 424 / 1,140
A6: Share of addressable assets (still at active customers) on maintenance | B6: =Inputs!$B$30/(Inputs!$B$30+Inputs!$B$35) -> 0.46902655 | C6: 424 / (424 + 480)
A7: Customer-level conversion the board uses | B7: =Inputs!$B$46/Inputs!$B$45 -> 0.34210526 | C7: 26 / 76 (Exhibit 4)
A8: Job-level conversion, LTM (nobody has calculated this) | B8: =Inputs!$B$47/Inputs!$B$21 -> 0.12068966 | C8: 7 / 58
A9: Net change in maintenance assets, LTM | B9: =Inputs!$B$47-Inputs!$B$48 -> -2 | C9: 7 added, 9 left
A10: Attrition rate, LTM | B10: =Inputs!$B$48/Inputs!$B$30 -> 0.021226415 | C10: 9 / 424
A11: Handshake revenue per year (176 assets, no contract) | B11: =Inputs!$B$32*'Unit economics'!$B$15 -> 1046037.7 | C11: Could walk at any time; carries no escalator
A12: share of Maintenance revenue on handshake terms | B12: =Inputs!$B$32/Inputs!$B$30 -> 0.41509434
A13: Escalator not being applied on handshake assets, per year | B13: =B11*Inputs!$B$39 -> 52301.887 | C13: 5% of handshake revenue, forgone every year and compounding
A14: Contracted revenue per year (248 assets) | B14: =Inputs!$B$31*'Unit economics'!$B$15 -> 1473962.3
A15: Escalator shortfall if 3% applied instead of 5% on contracted assets | B15: =B14*(Inputs!$B$39-Inputs!$B$40) -> 29479.245 | C15: Per year, if the one observed account is typical. To be checked.
A16: Known renewals due in 12 months: revenue | B16: =Inputs!$B$37*'Unit economics'!$B$15 -> 243679.25 | C16: 41 assets, no renewal process
A17: gross profit at risk | B17: =B16*Inputs!$B$9 -> 155954.72
A18: Renewals due if the two-thirds without expiry dates behave the same (estimate) | B18: =Inputs!$B$37/Inputs!$B$38 -> 124.24242 | C18: 41 is a floor, not the number
A19: Average renewals per year implied by 248 assets on five-year terms | B19: =Inputs!$B$31/5 -> 49.6 | C19: Sanity check on the line above
A20: Cross-sell population: 480 assets x revenue per asset-year | B20: =Inputs!$B$35*'Unit economics'!$B$15 -> 2852830.2 | C20: If every one enrolled
A21: gross profit per year if every one enrolled | B21: =B20*Inputs!$B$9 -> 1825811.3
A22: crew-weeks it would take to serve all 480 | B22: =Inputs!$B$35*Inputs!$B$20 -> 168 | C22: Against 220 available and already full
A23: Lapsed customers x average lifetime revenue | B23: =Inputs!$B$43*Inputs!$B$44 -> 10660000 | C23: 52 customers nobody has called. Illustrative of scale only.

Sheet Plan
A1: The plan: motions, assumptions, and what each produces in year one
A2: Yellow cells are my assumptions. Change any of them and the memo figures move. Conservative case: any new Restoration work is delivered by subcontractors at 15%, because the crews are full.
A4: Assumption or driver | B4: Value | I4: Basis
A5: A2: Handshake assets converted to signed agreements in year one | B5: 0.6 | I5: 68 customers already paying every year; the ask is a signature and the escalator
A6: A3: Year-one enrollment rate on the 480 cross-sell assets | B6: 0.15 | I6: A program assumption, not a trend. Organic adds last year were 7 across the whole base (under 2% of these 480). The 34% board figure and the 12% job-level rate are on different populations. Sensitivity below runs 5% to 25%.
A7: A4: Share of year-one enrollments that bill inside year one | B7: 0.5 | I7: Municipal budgets are annual; industrial can move in weeks (Exhibit 7)
A8: A5: Known renewals retained | B8: 0.85 | I8: No process exists today, so there is no baseline; this is a target
A9: A6: Incremental engineer or referral introductions from a run program | B9: 4 | I9: On a base of 36 inquiries per year from those two sources
A10: A7: Of those, awards inside year one | B10: 2 | I10: Assumption. The pack has no cycle data by source; warm introductions are assumed to land nearer the 11-month quartile than the 19-month median.
A11: A8: Multi-site parent portfolio awards in year one | B11: 1 | I11: Four parents, all held by the president
A12: A9: Systems per portfolio award | B12: 5 | I12: Assumption
A13: A10: Revenue per municipal system in a portfolio award | B13: 45000 | I13: Inside the $22K-65K municipal range
A14: A11: Lapsed customers reactivated in year one | B14: 5 | I14: About 10% of 52
A15: A12: Restoration jobs from reactivated customers | B15: 3 | I15: Assumption
A16: A13: Deficiency-list outbound awards in year one | B16: 0 | I16: Refused as a year-one revenue claim: the cycle is 19 months
... A19: A16: Share of portfolio-award systems that enroll in Maintenance | B19: 0.5 | I19: Above the base rate because the restoration is fresh and the parent relationship is held by the president; still an assumption
A21: Motion | B21: Start | C21: Year-one revenue | D21: Year-one gross profit | E21: Run-rate GP per year after year one | F21: Crew-weeks consumed (own crews) | G21: Program spend | H21: Provable? | I21: How the numbers are built
A22: 1a. Convert 176 handshake assets to signed agreements | B22: Q1 | C22: =Inputs!$B$32*Plan!$B$5*'Unit economics'!$B$15*Inputs!$B$39 -> 31381.132 | D22: =C22 -> 31381.132 | E22: =D22 -> 31381.132 | F22: 0 | G22: 10000 | H22: Inferred (no comparison group; the whole base is contacted) | I22: Escalator applied at signature on converted assets. Pure price on work already delivered, so it drops to gross profit at close to 100%. The real prize is securing five years of revenue that can walk today.
A23: 1b. Renewal process on agreements coming due | B23: Q1 | C23: =Inputs!$B$37*Plan!$B$8*'Unit economics'!$B$15 -> 207127.36 | D23: =C23*Inputs!$B$9 -> 132561.51 | E23: 0 | F23: 0 | G23: 5000 | H23: Not attributable; this is protected revenue, not new | I23: Protected, not incremental. Shown so it is not double counted. Excluded from the totals below.
A24: 1c. Cross-sell Maintenance to the 480 un-enrolled assets | B24: Q1 | C24: =Inputs!$B$35*Plan!$B$6*Plan!$B$7*'Unit economics'!$B$15 -> 213962.26 | D24: =C24*Inputs!$B$9 -> 136935.85 | E24: =Inputs!$B$35*Plan!$B$6*'Unit economics'!$B$16 -> 273871.7 | F24: =Inputs!$B$35*Plan!$B$6*Inputs!$B$20 -> 25.2 | G24: 40000 | H24: Provable: staggered rollout, half the accounts now, half in six months | I24: Enrollments x revenue per asset-year x share billing in year one. Spend covers packaging 20 years of before/after performance data per asset.
A25: 2. Run the referral and engineer channel as a program | B25: Q1 | C25: =Plan!$B$10*'Lead sources'!$I$9 -> 257714.29 | D25: =C25*Inputs!$B$26 -> 38657.143 | E25: =Plan!$B$9*'Lead sources'!$H$9*'Lead sources'!$I$9*Inputs!$B$26 -> 38657.143 | F25: 0 | G25: 30000 | H25: Inferred: introductions per quarter against last year's 36; no holdout possible on 8 firms | I25: Two in-year awards at the engineer average ticket, delivered by subcontractors (15%) because own crews are full. Run rate uses the 50% win rate on incremental introductions, also at 15%.
A26: 3. Multi-site utility parents: portfolio proposals | B26: Q2 | C26: =Plan!$B$11*Plan!$B$12*Plan!$B$13 -> 225000 | D26: =C26*Inputs!$B$26 -> 33750 | E26: =Plan!$B$11*Plan!$B$12*Plan!$B$19*'Unit economics'!$B$16 -> 9509.434 | F26: =Plan!$B$11*Plan!$B$12*Plan!$B$19*Inputs!$B$20 -> 0.875 | G26: 10000 | H26: Inferred: four accounts, all held by the president | I26: One portfolio award, subcontractor-delivered. Run rate assumes the systems enroll in Maintenance at A16; the crew-weeks are those visits.
A27: 4. Lapsed-customer outreach (52 customers) | B27: Q1 | C27: =Plan!$B$15*'Lead sources'!$B$19/'Lead sources'!$B$20 -> 172600 | D27: =C27*Inputs!$B$26 -> 25890 | E27: 0 | F27: 0 | G27: 5000 | H27: Provable: contact half now, half in Q3 | I27: Three repeat-sized jobs at last year's repeat average, subcontractor-delivered.
A28: 5. Deficiency-flagged outbound to the 190 top-tier fits | B28: Q2 | C28: 0 | D28: 0 | E28: 0 | F28: 0 | G28: 35000 | H28: Provable: matched split of the 190, contacted in two waves | I28: Zero revenue claimed in year one. Measured on first meetings, site visits and registered quotes. Revenue is a year-two answer.
A29: 6. Foundations: CRM asset records, source field, quote register, routed inbound, response commitment, website repair | B29: Q1 | C29: 0 | D29: 0 | E29: 0 | F29: 0 | G29: 45000 | H29: Not attributable; this is what makes the rest measurable | I29: CRM tier with custom objects sized to 900 companies and 1,140 assets, implementation help, website repair and routed form, call routing.
A30: 7. Paid pilot, industrial and remediation only (H2, only if the response commitment is live) | B30: Q3 | C30: 0 | D30: 0 | E30: 0 | F30: 0 | G30: 15000 | H30: Provable: pre-set cost per site visit rule | I30: Not counted. Kill rule: if cost per site visit exceeds $3,000 after $10K, stop.
A31: Totals (revenue and GP exclude 1b, which is protected revenue; spend includes it) | C31: =SUM(C22:C30)-C23 -> 900657.68 | D31: =SUM(D22:D30)-D23 -> 266614.12 | E31: =SUM(E22:E30)-E23 -> 353419.41 | F31: =SUM(F22:F30)-F23 -> 26.075 | G31: =SUM(G22:G30) -> 195000
A32: Contingency and measurement (analyst time, list data, holdout administration) | G32: =Inputs!$B$65-G31 -> 5000
A33: Budget check: total spend | G33: =G31+G32 -> 200000
A35: Displacement cost of the crew-weeks the plan consumes (cross-sell plus the portfolio systems)
A36: Crew-weeks the plan consumes at run rate | B36: =Plan!$F$31 -> 26.075
A37: Restoration jobs pushed to subcontractors to free them | B37: =B36/Inputs!$B$19 -> 10.028846
A38: Gross profit given up on those jobs | B38: =B37*Capacity!$B$23 -> 200996.17
A39: Run-rate Maintenance gross profit from the cross-sell and the portfolio systems | B39: =E24+E26 -> 283381.13
A40: Net gross profit per year after displacement | B40: =B39-B38 -> 82384.961
A41: Maintenance gross profit secured over five-year terms from year-one enrollments | B41: =E24*5 -> 1369358.5
A43: Year-one program return
A44: Year-one gross profit from the plan (conservative, subcontractor-delivered) | B44: =Plan!$D$31 -> 266614.12
A45: Program spend | B45: =Inputs!$B$65 -> 200000
A46: Year-one gross profit minus program spend, before displacement | B46: =B44-B45 -> 66614.124
...

Sheet Quarters
A1: Sequencing: what starts when, and why that order
A2: Order rule: shortest path to provable gross profit first, zero crew capacity first, and nothing that adds Restoration demand before the response commitment and the quote register exist.
A4: Quarter | B4: What happens | C4: Why here and not earlier or later
A5: Q1 | B5: Week 1: freeze the baseline lists (480, 176, 41, 52), mandatory source field, loss stage, quote register, asset-level CRM records, inbound routing with a named owner and a response commitment, capacity sheet. Weeks 2-13: handshake conversions (1a), renewal calendar (1b), cross-sell wave one to half the accounts (1c), referral ask built into project close-out, engineer program with the 8 firms (2), lapsed outreach wave one (4). Paid search and trade show spend stop. | C5: These customers already exist, so the 19-month cycle does not apply. Handshake and renewals consume no crew capacity. The instrumentation has to exist before anything else runs or nothing is measurable. Paid search lost money on gross profit last year and its leads had nowhere to land.
A6: Q2 | B6: Deficiency-flagged outbound wave one to half of the 190 top-tier fits (5). Multi-site parent portfolio maps for the president (3). Website repair and routed form live. First engineer case studies from the performance data. | C6: Outbound waits for the source field, quote register and response commitment, otherwise its results cannot be read. The president's four parents are the largest tickets and need the asset map, which takes the CRM work from Q1.
A7: Q3 | B7: Cross-sell wave two (the six-month wait group), lapsed wave two. Month-six decision rule on the cross-sell. Paid pilot for industrial and remediation only, if the response commitment is live and the kill rule is agreed. | C7: Wave two is what makes wave one a comparison rather than an anecdote. Industrial buyers spend from an appropriated budget and can move in weeks, so a small paid pilot there can be judged inside the year; municipal cannot.
A8: Q4 | B8: Outbound wave two to the second half of the 190, which has stayed untouched for two quarters. Renewal cycle repeats with all 248 agreement records populated. Twelve-month decision rules on outbound and the engineer program. Sixth-crew case built with finance from the capacity sheet. Year-two plan sized to whatever the comparisons showed. | C8: By Q4 the business has, for the first time, a denominator (quotes), a loss record, a source on every new record, and two contacted-versus-waiting comparisons. Year two gets planned from evidence rather than from the 34% figure.

Sheet Decision rules
A1: Decision rules, set before the results exist
A2: Numbers agreed in week one. The eight-week gate measures coverage and early installed-base signal; the real scale-or-stop calls are at month six and month twelve.
A4: When | B4: Measure | C4: Rule | D4: If it misses
A5: Week 8 | B5: All 480 cross-sell assets, 176 handshake assets and 41 renewals loaded with an owner and a contact | C5: 100% | D5: Coverage is the one thing entirely in my control. A miss here is on me.
A6: Week 8 | B6: New CRM records with a source recorded | C6: 95% or more | D6: Field is not mandatory; fix the form.
A7: Week 8 | B7: Median response time on inbound inquiries | C7: Under one business day | D7: Routing or ownership is wrong; fix before any demand spend.
A8: Week 8 | B8: Handshake assets converted to a signed agreement | C8: 20 or more (about 11% of 176) | D8: Below 10: the offer is wrong, likely the escalator; revisit terms before continuing.
A9: Week 8 | B9: Cross-sell assets enrolled or in procurement | C9: 12 or more (2.5% of 480) | D9: Below 6: pause wave one, diagnose, do not kill; eight weeks is short against a 14-month median.
A10: Week 8 | B10: Restoration new-customer revenue attributable to marketing | C10: Not reported | D10: Cannot be known honestly at eight weeks. Will say so on the page.
A11: Month 6 | B11: Cross-sell enrollment rate, contacted accounts vs six-month-wait accounts | C11: 8 points or more higher: scale to the full base. Under 3 points: stop and move the budget to motions 2 and 5. | D11: Between 3 and 8: continue one more quarter with the wait group still waiting.
A12: Month 6 | B12: Lapsed customers reactivated, contacted half vs waiting half | C12: 3 or more from the contacted half and 0 or 1 from the waiting half | D12: Otherwise stop; the 52 are lapsed for a reason.
A13: Month 9 | B13: Deficiency outbound: first meetings, site visits, registered quotes, wave one (contacted in Q2) vs wave two (untouched until Q4) | C13: 15 meetings and 5 site visits from wave one against 2 or fewer from the untouched group | D13: Otherwise stop and put year-two effort into engineers and parents.
A14: Month 12 | B14: Engineer and referral introductions | C14: 40 or more against last year's 36 (A6: plus four) | D14: Trend only; eight firms is too few for a comparison group. Say so.
A15: Month 12 | B15: Paid pilot (industrial and remediation) | C15: Cost per site visit under $3,000 after $10K | D15: Stop at $10K if the rule is missed.
A16: Month 18+ | B16: Marketing-attributed new-customer Restoration revenue | C16: Reported for the first time, by cohort of first contact | D16: This is the earliest honest date, given a 19-month median cycle.

Sheet Trust checks
A1: Figures I do not fully believe, with the arithmetic behind each
A2: Each row: the figure, the check, what the check shows.
A4: Check | B4: Value | C4: What it says
A5: New customers per year (Exhibit 6) | B5: =Inputs!$B$52 -> 28 | C5: 28 new customers in twelve months
A6: x 3.6 years since January 2023 | B6: =B5*3.6 -> 100.8 | C6: About 100 new Restoration customers since 2023 at that pace
A7: Restoration customers of any kind since January 2023 (Exhibit 4) | B7: =Inputs!$B$45 -> 76 | C7: Only 76, new and repeat together. The two cannot both be right unless new-logo wins roughly tripled this year.
A8: x 8 years | B8: =B5*8 -> 224 | C8: 224 at that pace
A9: Distinct customers in eight years (Exhibit 2) | B9: =Inputs!$B$41 -> 164 | C9: 164. Same problem. Check what 'new customer' means in Exhibit 6 (new to the CRM? new contact at an old customer?).
A10: Crew-week arithmetic (Exhibit 5) | B10: =Capacity!$B$8 -> 299.2 | C10: 299 crew-weeks of work against 220 available
A11: reconciles if this many jobs were subcontracted | B11: =Capacity!$B$11 -> 30.461538 | C11: About 30 jobs at about $54K each. Self-performed work then lands at 220 crew-weeks against 220 available: full to the week. Reconciles, but only under A1.
A12: 'Top decile' label on the 190 (Exhibit 8): share of national universe | B12: =Inputs!$B$56/Inputs!$B$55 -> 0.001484375 | C12: 0.15%, not 10%
A13: share of the scored population (190 + 4,100) | B13: =Inputs!$B$56/(Inputs!$B$56+Inputs!$B$57) -> 0.044289044 | C13: 4.4%, not 10%
A14: share of the five licensed states | B14: =Inputs!$B$56/Inputs!$B$60 -> 0.0097938144 | C14: 1%, not 10%. The 190 may be excellent; 'top decile' is not what it is.
A15: Lifetime revenue implied by Exhibit 2: 164 x $205K | B15: =Inputs!$B$41*Inputs!$B$44 -> 33620000 | C15: $33.6M
A16: revenue two years ago | B16: =Inputs!$B$5/(1+Inputs!$B$15) -> 7368421.1 | C16: $7.37M
A17: rough eight-year customer revenue if growth was steady at the two-year rate, excluding licensing | B17: =SUMPRODUCT(Inputs!$B$5*(1+Inputs!$B$15)^(-{0,1,2,3,4,5,6,7}/2))-8*Inputs!$B$12 -> 51346054 | C17: Around $50M. Exhibit 2's lifetime figure is short by a third. Either 'lifetime' means something narrower or the $205K is stale.
A18: Renewals due (Exhibit 3): known | B18: =Inputs!$B$37 -> 41 | C18: From the third of records with a date
A19: estimate if the other two-thirds are similar | B19: ='Installed base'!$B$18 -> 124.24242 | C19: Roughly 120. Against 248 on five-year terms (about 50 a year on average) that is high, so the truth is likely between 41 and 120. Populate every expiry date in week one.
A20: Maintenance revenue growth over two years implied by Exhibit 1 | B20: =Inputs!$B$8/(Inputs!$B$5/(1+Inputs!$B$15)*Inputs!$B$16)-1 -> 0.06875 | C20: About 7% over two years, on a base that lost assets net. Escalator on 58% of assets explains most of it only if it was actually applied at 5%. Consistent with the 3% observation not being typical, or with price increases elsewhere. Check the invoices.
A21: Email: government open rate (Exhibit 7) | B21: 0.71 | C21: Double the private-sector rate, with every link clicked within seconds: security scanners, not people. Every open and click figure in the pack is contaminated. Do not use them.
A22: Paid search conversion as presented (Exhibit 6) | B22: ='Lead sources'!H5 -> 0.0095238095 | C22: Mixes this year's 210 inquiries with wins whose first contact was mostly more than a year ago (Exhibit 7). Not a conversion rate; a cohort mismatch.
A23: Customers who bought exactly once in eight years (Exhibit 2) | B23: =Inputs!$B$41-154 -> 10 | C23: Ten. If 28 customers were new last year, at least 18 of them have already bought a second time inside twelve months, in a business with a 19-month cycle. Another reason the 28 does not hold.
A24: Own-crew revenue two years ago, if subcontracting was near zero then | B24: =Inputs!$B$5/(1+Inputs!$B$15)-Inputs!$B$28/Inputs!$B$27*Inputs!$B$25 -> 7325442.5 | C24: Roughly $7.3M
A25: own-crew revenue now (Exhibit 5) | B25: =Inputs!$B$23 -> 6759000 | C25: $6.76M. If subcontracted work went from near zero to $1.64M while revenue grew $1.03M, the crews delivered about half a million less than two years ago. A crew lost, a shift toward 0.35-week visits, or a large job bought whole. Check: crew count and hours by year.
A26: Win rate | B26: n/a | C26: Unknowable from the records: no quote register, zero losses recorded in six years. Starts from zero on day one.
